问题:

出现问题原因是之前用的python环境是3.8,但是在使用celery过程中一直报错,网上查阅发现了,celery对windows环境的支持情况和在windows下运行的python版本有关系,所以换了python 3.6版本;

然后发现换了之后出现了上述问题;

解决方法是:

找到之前使用的虚拟环境中的  '0009_auto_20200720_0228'  文件和对应的缓存文件

拷贝到现在虚拟环境的对应目录下;再次运行没有报错消失

